<?xml version="1.0" ?>
<!-- =================================================================================== -->
<!-- |    This document was autogenerated by xacro from two_wheel_robot.xacro          | -->
<!-- |    EDITING THIS FILE BY HAND IS NOT RECOMMENDED                                 | -->
<!-- =================================================================================== -->
<robot name="two_wheel_robot">
  <!-- 底盘 -->
  <link name="base_link">
    <visual>
      <geometry>
        <box size="0.3 0.2 0.1"/>
      </geometry>
      <material name="red"/>
    </visual>
    <collision>
      <geometry>
        <box size="0.3 0.2 0.1"/>
      </geometry>
    </collision>
    <!-- 完整惯性矩阵 -->
    <inertial>
      <mass value="1.0"/>
      <inertia ixx="0.01" ixy="0.0" ixz="0.0" iyy="0.01" iyz="0.0" izz="0.01"/>
    </inertial>
  </link>
  <gazebo reference="base_link">
    <material>Gazebo/Red</material>
  </gazebo>
  <link name="left_wheel">
    <visual>
      <geometry>
        <cylinder length="0.02" radius="0.05"/>
      </geometry>
      <material name="black"/>
    </visual>
    <collision>
      <geometry>
        <cylinder length="0.02" radius="0.05"/>
      </geometry>
    </collision>
    <!-- 完整惯性矩阵，修复Gazebo报错 -->
    <inertial>
      <mass value="0.1"/>
      <inertia ixx="0.0005" ixy="0.0" ixz="0.0" iyy="0.0005" iyz="0.0" izz="0.0005"/>
    </inertial>
  </link>
  <joint name="left_joint" type="continuous">
    <parent link="base_link"/>
    <child link="left_wheel"/>
    <origin rpy="1.5708 0 0" xyz="0.0 0.11 -0.05"/>
    <!-- 终极正确：转轴垂直轮子圆面 -->
    <axis xyz="0 0 1"/>
  </joint>
  <gazebo reference="left_wheel">
    <material>Gazebo/Black</material>
  </gazebo>
  <link name="right_wheel">
    <visual>
      <geometry>
        <cylinder length="0.02" radius="0.05"/>
      </geometry>
      <material name="black"/>
    </visual>
    <collision>
      <geometry>
        <cylinder length="0.02" radius="0.05"/>
      </geometry>
    </collision>
    <!-- 完整惯性矩阵，修复Gazebo报错 -->
    <inertial>
      <mass value="0.1"/>
      <inertia ixx="0.0005" ixy="0.0" ixz="0.0" iyy="0.0005" iyz="0.0" izz="0.0005"/>
    </inertial>
  </link>
  <joint name="right_joint" type="continuous">
    <parent link="base_link"/>
    <child link="right_wheel"/>
    <origin rpy="1.5708 0 0" xyz="0.0 -0.11 -0.05"/>
    <!-- 终极正确：转轴垂直轮子圆面 -->
    <axis xyz="0 0 1"/>
  </joint>
  <gazebo reference="right_wheel">
    <material>Gazebo/Black</material>
  </gazebo>
  <!-- 万向轮 -->
  <link name="caster_wheel">
    <visual>
      <geometry>
        <sphere radius="0.03"/>
      </geometry>
      <material name="gray"/>
    </visual>
    <collision>
      <geometry>
        <sphere radius="0.03"/>
      </geometry>
    </collision>
    <inertial>
      <mass value="0.05"/>
      <inertia ixx="0.0001" ixy="0.0" ixz="0.0" iyy="0.0001" iyz="0.0" izz="0.0001"/>
    </inertial>
  </link>
  <joint name="caster_joint" type="fixed">
    <parent link="base_link"/>
    <child link="caster_wheel"/>
    <origin xyz="-0.12 0 -0.06"/>
  </joint>
  <gazebo reference="caster_wheel">
    <material>Gazebo/Gray</material>
  </gazebo>
  <!-- 差速驱动插件 -->
  <gazebo>
    <plugin filename="libgazebo_ros_diff_drive.so" name="differential_drive_controller">
      <alwaysOn>true</alwaysOn>
      <leftJoint>left_joint</leftJoint>
      <rightJoint>right_joint</rightJoint>
      <wheelSeparation>0.22</wheelSeparation>
      <wheelDiameter>0.1</wheelDiameter>
      <torque>10</torque>
      <commandTopic>cmd_vel</commandTopic>
    </plugin>
  </gazebo>
</robot>

